<?xml version="1.0" ?>
<robot name="dummy_robot" xmlns:xacro="http://ros.org/wiki/xacro">
  <xacro:include filename="$(find dummy_robot_description)/urdf/common_properties.xacro"/>
  <xacro:include filename="$(find dummy_robot_description)/urdf/dummy_robot.gazebo.xacro"/>

  <xacro:property name="CADscale" value="0.0012" />


<!-- ============ 'base_footprint' is the ground link ===================== -->
  <link name="dummy_base_footprint"/>

  <joint name="base_joint" type="fixed">
    <parent link="dummy_base_footprint"/>
    <child link="dummy_base_link"/>
    <!-- dummy_base_link is placed at the center of gravity of GoPiGo3 body -->
    <origin xyz="0 0 0.075" rpy="0 0 0"/>
  </joint>

<!-- ============ 'dummy_base_link' simulates GoPiGo3 body mass and moment of inertia
                   and act as the robot reference frame =================== -->
  <link name="dummy_base_link">
  <!-- **** 'dummy_base_link' COLLISION & INERTIA **** -->
    <collision>
      <origin xyz="-0.038 0 0.07" rpy="0 0 0"/>
      <geometry>
        <box size="0.245 0.15 0.25"/>
      </geometry>
    </collision>

    <inertial>
      <origin xyz="-0.02 0 0" rpy="0 0 0"/>
      <mass value="0.534"/>
      <inertia ixx="1.0e-03" ixy="0" ixz="0"
               iyy="1.0e-03" iyz="0"
               izz="2.45e-03" />
    </inertial>

    <visual>
      <origin xyz="-0.038 0 0.07" rpy="0 0 0"/>
      <geometry>
        <box size="0.3 0.15 0.25"/>
      </geometry>
    </visual>

  </link>


<!-- ============ wheel_left ====================== -->
  <joint name="wheel_left_joint" type="continuous">
    <parent link="dummy_base_link"/>
    <child link="wheel_left_link"/>
    <origin xyz="0 0.089 -0.042" rpy="0 0 1.57"/>
    <axis xyz="1 0 0"/>
  </joint>

  <link name="wheel_left_link">
    <visual>
      <origin xyz="0 0 0" rpy="0 1.57 0"/>
      <geometry>
        <cylinder length="0.026" radius="0.033"/>
      </geometry>
      <material name="black"/>
    </visual>

    <collision>
      <origin xyz="0 0 0" rpy="0 1.57 0"/>
      <geometry>
        <cylinder length="0.026" radius="0.033"/>
      </geometry>
    </collision>

    <inertial>
      <origin xyz="0 0 0" />
      <mass value="0.032" />
      <inertia ixx="1.74e-05" ixy="0" ixz="0"
               iyy="1.05e-05" iyz="0"
               izz="1.05e-05" />
    </inertial>
  </link>

<!-- ============ wheel_right ====================== -->
  <joint name="wheel_right_joint" type="continuous">
    <parent link="dummy_base_link"/>
    <child link="wheel_right_link"/>
    <origin xyz="0 -0.089 -0.042" rpy="0 0 -1.57"/>
    <axis xyz="-1 0 0"/>
  </joint>

  <link name="wheel_right_link">
    <visual>
      <origin xyz="0 0 0" rpy="0 1.57 0"/>
      <geometry>
        <cylinder length="0.026" radius="0.033"/>
      </geometry>
      <material name="black"/>
    </visual>

    <collision>
      <origin xyz="0 0 0" rpy="0 1.57 0"/>
      <geometry>
        <cylinder length="0.026" radius="0.033"/>
      </geometry>
    </collision>

    <inertial>
      <origin xyz="0 0 0" />
      <mass value="0.032" />
      <inertia ixx="1.74e-05" ixy="0" ixz="0"
               iyy="1.05e-05" iyz="0"
               izz="1.05e-05" />
    </inertial>
  </link>

<!-- ============ caster_back ====================== -->
  <joint name="caster_back_joint" type="fixed">
    <parent link="dummy_base_link"/>
    <child link="caster_back_link"/>
    <origin xyz="-0.132 0 -0.075" rpy="0 0 0"/>
  </joint>

  <link name="caster_back_link">
    <collision>
      <origin xyz="0 0 0.01" rpy="1.57 0 0"/>
      <geometry>
        <cylinder length="0.009" radius="0.01"/>
      </geometry>
    </collision>

    <visual>
      <origin xyz="0 0 0.01" rpy="1.57 0 0"/>
      <geometry>
        <cylinder length="0.009" radius="0.01"/>
      </geometry>
    </visual>

    <inertial>
      <origin xyz="0 0 0" />
      <mass value="0.005" />
      <inertia ixx="0.001" ixy="0.0" ixz="0.0"
               iyy="0.001" iyz="0.0"
               izz="0.001" />
    </inertial>
  </link>
</robot>
